[04-Dec-22 15:07:12] ERROR - Exception occurred
Traceback (most recent call last):
  File "c:\Users\ckiokak\Documents\Abstract_Microservices\unified_exceptions.py", line 10, in function
    return func(*args, **kwargs)
  File "c:\Users\ckiokak\Documents\Abstract_Microservices\unified_exceptions.py", line 20, in dia
    return a/b
ZeroDivisionError: division by zero
[04-Dec-22 18:53:20] ERROR - Exception occurred
Traceback (most recent call last):
  File "C:\Users\ckiokak\Documents\Abstract_Microservices\unified_exceptions.py", line 10, in function
    return func(*args, **kwargs)
  File "C:\Users\ckiokak\Documents\Abstract_Microservices\dummyDB.py", line 37, in create_connection
    connection = psycopg2.connect(
  File "C:\Python\Python10\lib\site-packages\psycopg2\__init__.py", line 122, in connect
    conn = _connect(dsn, connection_factory=connection_factory, **kwasync)
psycopg2.OperationalError: connection to server at "127.0.0.1", port 5432 failed: FATAL:  database "firstdb" does not exist

[04-Dec-22 18:53:20] INFO - Connection to PostgreSQL DB 'postgres' successful
[04-Dec-22 18:53:20] INFO - Database created successfully
[04-Dec-22 18:53:20] INFO - Connection to PostgreSQL DB 'firstdb' successful
